[2025-04-14T10:50:43.075+0000] {taskinstance.py:1956} INFO - Dependencies all met for dep_context=non-requeueable deps ti=<TaskInstance: dag_task.print_random_quote manual__2025-04-14T10:50:15.914151+00:00 [queued]>
[2025-04-14T10:50:43.117+0000] {taskinstance.py:1956} INFO - Dependencies all met for dep_context=requeueable deps ti=<TaskInstance: dag_task.print_random_quote manual__2025-04-14T10:50:15.914151+00:00 [queued]>
[2025-04-14T10:50:43.118+0000] {taskinstance.py:2170} INFO - Starting attempt 1 of 1
[2025-04-14T10:50:43.168+0000] {taskinstance.py:2191} INFO - Executing <Task(PythonOperator): print_random_quote> on 2025-04-14 10:50:15.914151+00:00
[2025-04-14T10:50:43.173+0000] {standard_task_runner.py:60} INFO - Started process 242 to run task
[2025-04-14T10:50:43.177+0000] {standard_task_runner.py:87} INFO - Running: ['airflow', 'tasks', 'run', 'dag_task', 'print_random_quote', 'manual__2025-04-14T10:50:15.914151+00:00', '--job-id', '8', '--raw', '--subdir', 'DAGS_FOLDER/dag_task.py', '--cfg-path', '/tmp/tmp1vf16k6z']
[2025-04-14T10:50:43.179+0000] {standard_task_runner.py:88} INFO - Job 8: Subtask print_random_quote
[2025-04-14T10:50:43.328+0000] {task_command.py:423} INFO - Running <TaskInstance: dag_task.print_random_quote manual__2025-04-14T10:50:15.914151+00:00 [running]> on host bb379e170722
[2025-04-14T10:50:43.757+0000] {taskinstance.py:2480} INFO - Exporting env vars: AIRFLOW_CTX_DAG_OWNER='airflow' AIRFLOW_CTX_DAG_ID='dag_task' AIRFLOW_CTX_TASK_ID='print_random_quote' AIRFLOW_CTX_EXECUTION_DATE='2025-04-14T10:50:15.914151+00:00' AIRFLOW_CTX_TRY_NUMBER='1' AIRFLOW_CTX_DAG_RUN_ID='manual__2025-04-14T10:50:15.914151+00:00'
[2025-04-14T10:50:43.762+0000] {taskinstance.py:2698} ERROR - Task failed with exception
Traceback (most recent call last):
  File "/home/airflow/.local/lib/python3.8/site-packages/airflow/models/taskinstance.py", line 433, in _execute_task
    result = execute_callable(context=context, **execute_callable_kwargs)
  File "/home/airflow/.local/lib/python3.8/site-packages/airflow/operators/python.py", line 199, in execute
    return_value = self.execute_callable()
  File "/home/airflow/.local/lib/python3.8/site-packages/airflow/operators/python.py", line 216, in execute_callable
    return self.python_callable(*self.op_args, **self.op_kwargs)
  File "/opt/airflow/dags/dag_task.py", line 27, in print_random_quote
    response = requests.get('<replace valid url here>')
  File "/home/airflow/.local/lib/python3.8/site-packages/requests/api.py", line 73, in get
    return request("get", url, params=params, **kwargs)
  File "/home/airflow/.local/lib/python3.8/site-packages/requests/api.py", line 59, in request
    return session.request(method=method, url=url, **kwargs)
  File "/home/airflow/.local/lib/python3.8/site-packages/requests/sessions.py", line 575, in request
    prep = self.prepare_request(req)
  File "/home/airflow/.local/lib/python3.8/site-packages/requests/sessions.py", line 486, in prepare_request
    p.prepare(
  File "/home/airflow/.local/lib/python3.8/site-packages/requests/models.py", line 368, in prepare
    self.prepare_url(url, params)
  File "/home/airflow/.local/lib/python3.8/site-packages/requests/models.py", line 439, in prepare_url
    raise MissingSchema(
requests.exceptions.MissingSchema: Invalid URL '<replace valid url here>': No scheme supplied. Perhaps you meant https://<replace valid url here>?
[2025-04-14T10:50:43.846+0000] {taskinstance.py:1138} INFO - Marking task as FAILED. dag_id=dag_task, task_id=print_random_quote, execution_date=20250414T105015, start_date=20250414T105043, end_date=20250414T105043
[2025-04-14T10:50:44.009+0000] {standard_task_runner.py:107} ERROR - Failed to execute job 8 for task print_random_quote (Invalid URL '<replace valid url here>': No scheme supplied. Perhaps you meant https://<replace valid url here>?; 242)
[2025-04-14T10:50:44.038+0000] {local_task_job_runner.py:234} INFO - Task exited with return code 1
[2025-04-14T10:50:44.095+0000] {taskinstance.py:3280} INFO - 0 downstream tasks scheduled from follow-on schedule check
